注意了抛出错误 throw new Error势必会造成服务器错误 谨慎使用它


```js
// 错误日志
app.use(async (ctx, next) => {
  try {
    await next()
    // 401==>造成语法错误被这里捕获,显然不对,非2XX的都可能造成语法错误，所以不应该现在这里被捕获，这里主要捕获服务器错误❌的
  } catch (err) {
    app.use(morgan('combined', { stream: errorLogStream }))
  }
})

```
